Workbook

Sheet F1
A1: Subsystem | B1: Purpose | C1: Inputs | D1: Outputs | E1: Risks | F1: Interfaces | G1: Metrics | H1: Externalities
A2: Decision Systems & Mandates | B2: Define how decisions are made, by whom, under what authority | C2: Mandates, roles, constraints, data, proposals | D2: Decisions, approvals, rejections, rationale | E2: Unclear authority, decision bottlenecks, capture | F2: F3 (data), F4 (feedback), F5 (incentives) | G2: Decision latency, decision accuracy, mandate clarity | H2: Power concentration, opaque decisions
A3: Institutional Architecture & Roles | B3: Define structure, roles, responsibilities | C3: Org charts, mandates, legal constraints | D3: Role definitions, responsibility maps | E3: Role ambiguity, duplication, gaps | F3: F8 (integration), F10 (standards) | G3: Role clarity, overlap index | H3: Institutional rigidity
A4: Transparency & Public Records | B4: Ensure decisions and actions are visible | C4: Logs, decisions, data, records | D4: Public records, disclosures | E4: Hidden actions, incomplete records | F4: F3 (audit), F4 (feedback) | G4: Transparency coverage, record completeness | H4: Privacy leakage
A5: Accountability & Oversight | B5: Detect and correct misuse, errors, misconduct | C5: Reports, audits, complaints | D5: Corrective actions, sanctions | E5: Oversight capture, weak enforcement | F5: F3 (audit), F5 (incentives) | G5: Oversight response time, enforcement rate | H5: Chilling effects
A6: Ethics, Integrity & Anti‑Corruption | B6: Prevent corruption, conflicts, unethical behaviour | C6: Declarations, audits, incentives | D6: Integrity reports, conflict flags | E6: Corruption, conflicts of interest | F6: F5 (incentives), F3 (audit) | G6: Conflict detection rate, integrity score | H6: Over‑compliance burden
A7: Dispute Resolution & Redress | B7: Resolve disputes fairly and consistently | C7: Complaints, evidence, rules | D7: Resolutions, remedies | E7: Bias, backlog, inconsistent rulings | F7: F4 (feedback), F1 (mandates) | G7: Resolution time, fairness index | H7: Strategic complaints
A8: Delegation & Escalation Paths | B8: Ensure decisions escalate or delegate correctly | C8: Mandates, thresholds, workflows | D8: Escalation events, delegated actions | E8: Escalation failure, overload | F8: F2 (risk), F8 (integration) | G8: Escalation correctness, overload frequency | H8: Over‑centralisation
A9: Legitimacy & Consent Maintenance | B9: Maintain public trust and consent | C9: Sentiment, participation, transparency | D9: Legitimacy signals, trust reports | E9: Loss of legitimacy, disengagement | F9: F4 (feedback), F5 (behaviour) | G9: Trust index, participation rate | H9: Populist capture

Sheet F2
A1: Subsystem | B1: Purpose | C1: Inputs | D1: Outputs | E1: Risks | F1: Interfaces | G1: Metrics | H1: Externalities
A2: Hazard Detection & Early Warning | B2: Detect emerging risks early | C2: Sensors, reports, data streams | D2: Alerts, warnings | E2: Missed signals, false positives | F2: F3 (data), F7 (ecology) | G2: Detection latency, false‑positive rate | H2: Alarm fatigue
A3: Risk Assessment & Prioritisation | B3: Rank risks by severity and likelihood | C3: Hazard data, models | D3: Risk scores, priority lists | E3: Mis‑prioritisation, bias | F3: F5 (behaviour), F8 (integration) | G3: Prioritisation accuracy | H3: Resource misallocation
A4: Crisis Coordination | B4: Coordinate multi‑actor response | C4: Alerts, resources, mandates | D4: Coordinated actions | E4: Coordination failure | F4: F1 (governance), F6 (infrastructure) | G4: Response time, coordination score | H4: Over‑centralisation
A5: Continuity Planning | B5: Ensure operations survive disruptions | C5: Dependencies, workflows | D5: Continuity plans | E5: Plan failure, outdated plans | F5: F8 (integration), F6 (infra) | G5: Continuity coverage | H5: Over‑resilience cost
A6: Escalation & De‑escalation | B6: Manage crisis intensity | C6: Thresholds, signals | D6: Escalation events | E6: Late escalation, premature de‑escalation | F6: F1 (delegation), F4 (feedback) | G6: Escalation correctness | H6: Panic amplification
A7: Resource Mobilisation | B7: Deploy resources efficiently | C7: Inventories, logistics | D7: Resource deployments | E7: Shortages, misallocation | F7: F6 (infra), F2 (coordination) | G7: Deployment speed | H7: Resource depletion
A8: Post‑Incident Review | B8: Learn from failures | C8: Logs, outcomes | D8: Lessons, recommendations | E8: Blame games, ignored lessons | F8: F3 (audit), F1 (oversight) | G8: Lesson adoption rate | H8: Over‑correction
A9: Cross‑System Synchronisation | B9: Align responses across systems | C9: Signals, dependencies | D9: Synchronised actions | E9: Desynchronisation | F9: F8 (integration) | G9: Sync accuracy | H9: Cascading failures

Sheet F3
A1: Subsystem | B1: Purpose | C1: Inputs | D1: Outputs | E1: Risks | F1: Interfaces | G1: Metrics | H1: Externalities
A2: Data Provenance & Lineage | B2: Track where data comes from | C2: Raw data, metadata | D2: Provenance chains | E2: Missing lineage | F2: F9 (records), F10 (standards) | G2: Provenance completeness | H2: Privacy exposure
A3: Validation & Verification | B3: Ensure data is correct | C3: Data, schemas | D3: Validated data | E3: Invalid data passing | F3: F5 (behaviour), F3 (audit) | G3: Validation accuracy | H3: Over‑strict validation
A4: Audit Trails & Logging | B4: Record actions and changes | C4: Events, actions | D4: Logs | E4: Log tampering | F4: F1 (oversight) | G4: Log completeness | H4: Storage overhead
A5: Quality Assurance | B5: Maintain data quality | C5: Data, rules | D5: QA reports | E5: Quality drift | F5: F8 (integration) | G5: Error rate | H5: Over‑cleaning
A6: Tamper Detection | B6: Detect manipulation | C6: Logs, hashes | D6: Alerts | E6: Undetected tampering | F6: F2 (risk) | G6: Detection rate | H6: False alarms
A7: Access Control Audit | B7: Ensure correct access | C7: Permissions, logs | D7: Access reports | E7: Privilege creep | F7: F9 (auth) | G7: Access violations | H7: Over‑restriction
A8: Data Retention & Archival | B8: Preserve data correctly | C8: Records, policies | D8: Archives | E8: Loss, corruption | F8: F10 (standards) | G8: Retention compliance | H8: Storage cost
A9: Cross‑System Reconciliation | B9: Align data across systems | C9: Multiple datasets | D9: Reconciled data | E9: Inconsistency | F9: F8 (integration) | G9: Reconciliation accuracy | H9: Forced uniformity

Sheet F4
A1: Subsystem | B1: Purpose | C1: Inputs | D1: Outputs | E1: Risks | F1: Interfaces | G1: Metrics | H1: Externalities
A2: Sentiment & Narrative Monitoring | B2: Track public mood | C2: Media, surveys | D2: Sentiment signals | E2: Misinterpretation | F2: F5 (behaviour) | G2: Sentiment accuracy | H2: Manipulation
A3: Public Feedback Channels | B3: Capture public input | C3: Forms, calls | D3: Feedback data | E3: Low participation | F3: F1 (legitimacy) | G3: Participation rate | H3: Feedback overload
A4: Cultural Signal Tracking | B4: Track cultural shifts | C4: Trends, events | D4: Cultural indicators | E4: Bias | F4: F7 (ecology) | G4: Cultural drift | H4: Cultural homogenisation
A5: Community Engagement | B5: Maintain community ties | C5: Meetings, outreach | D5: Engagement reports | E5: Tokenism | F5: F4 (feedback) | G5: Engagement depth | H5: Over‑consultation
A6: Complaint & Redress Intake | B6: Capture grievances | C6: Complaints | D6: Cases | E6: Backlogs | F6: F1 (redress) | G6: Resolution time | H6: Strategic complaints
A7: Trust & Legitimacy Monitoring | B7: Track trust levels | C7: Sentiment, behaviour | D7: Trust reports | E7: Misreading trust | F7: F1 (legitimacy) | G7: Trust index | H7: Trust manipulation
A8: Public Information & Communication | B8: Communicate clearly | C8: Data, decisions | D8: Public messages | E8: Misinformation | F8: F2 (risk) | G8: Clarity score | H8: Over‑communication
A9: Cultural Impact Assessment | B9: Assess cultural effects | C9: Policies, actions | D9: Impact reports | E9: Blind spots | F9: F5 (behaviour) | G9: Impact accuracy | H9: Cultural distortion

Sheet F5
A1: Subsystem | B1: Purpose | C1: Inputs | D1: Outputs | E1: Risks | F1: Interfaces | G1: Metrics | H1: Externalities
A2: Behavioural Modelling | B2: Predict behaviour | C2: Data, signals | D2: Models | E2: Wrong predictions | F2: F3 (data) | G2: Model accuracy | H2: Behavioural stereotyping
A3: Incentive Design | B3: Shape behaviour | C3: Goals, models | D3: Incentives | E3: Perverse incentives | F3: F1 (governance) | G3: Incentive effectiveness | H3: Gaming
A4: Influence Mapping | B4: Map influence flows | C4: Networks, data | D4: Influence maps | E4: Misidentification | F4: F4 (culture) | G4: Influence accuracy | H4: Stigmatisation
A5: Motivation & Compliance | B5: Maintain compliance | C5: Rules, incentives | D5: Compliance signals | E5: Non‑compliance | F5: F10 (standards) | G5: Compliance rate | H5: Over‑policing
A6: Perverse Incentive Detection | B6: Detect harmful incentives | C6: Behaviour data | D6: Alerts | E6: Missed incentives | F6: F2 (risk) | G6: Detection rate | H6: False positives
A7: Behavioural Impact Assessment | B7: Evaluate interventions | C7: Data, models | D7: Impact reports | E7: Misattribution | F7: F8 (integration) | G7: Impact accuracy | H7: Over‑attribution
A8: Feedback Loop Design | B8: Create adaptive loops | C8: Signals, incentives | D8: Loops | E8: Instability | F8: F4 (feedback) | G8: Loop stability | H8: Over‑tight coupling
A9: Behavioural Risk Monitoring | B9: Track behavioural risks | C9: Signals, models | D9: Risk alerts | E9: Blind spots | F9: F2 (risk) | G9: Risk detection | H9: Behavioural panic

Sheet F6
A1: Subsystem | B1: Purpose | C1: Inputs | D1: Outputs | E1: Risks | F1: Interfaces | G1: Metrics | H1: Externalities
A2: Energy Systems | B2: Provide energy | C2: Fuel, grid data | D2: Power | E2: Outages | F2: F2 (risk) | G2: Uptime | H2: Emissions
A3: Water & Waste Systems | B3: Provide water, manage waste | C3: Water, waste | D3: Clean water, disposal | E3: Contamination | F3: F7 (ecology) | G3: Quality index | H3: Pollution
A4: Transport & Logistics | B4: Move people & goods | C4: Vehicles, routes | D4: Transport | E4: Congestion | F4: F8 (integration) | G4: Throughput | H4: Emissions
A5: Digital Infrastructure | B5: Provide connectivity | C5: Networks | D5: Connectivity | E5: Outages | F5: F9 (protocols) | G5: Latency | H5: Surveillance
A6: Material Supply Chains | B6: Provide materials | C6: Suppliers | D6: Materials | E6: Shortages | F6: F2 (risk) | G6: Supply stability | H6: Resource depletion
A7: Facilities & Asset Management | B7: Manage buildings | C7: Assets | D7: Facilities | E7: Decay | F7: F6 (infra) | G7: Maintenance score | H7: Over‑building
A8: Maintenance & Lifecycle Planning | B8: Maintain assets | C8: Schedules | D8: Maintenance | E8: Failure | F8: F2 (risk) | G8: Failure rate | H8: Over‑maintenance
A9: Infrastructure Resilience | B9: Ensure robustness | C9: Stress tests | D9: Resilience plans | E9: Collapse | F9: F8 (integration) | G9: Resilience index | H9: Over‑redundancy

Sheet F7
A1: Subsystem | B1: Purpose | C1: Inputs | D1: Outputs | E1: Risks | F1: Interfaces | G1: Metrics | H1: Externalities
A2: Climate Monitoring | B2: Track climate | C2: Sensors | D2: Climate signals | E2: Blind spots | F2: F2 (risk) | G2: Accuracy | H2: Alarm fatigue
A3: Biodiversity Health | B3: Track ecosystems | C3: Surveys | D3: Biodiversity index | E3: Miscounts | F3: F7 (ecology) | G3: Species index | H3: Over‑intervention
A4: Pollution Tracking | B4: Track pollutants | C4: Sensors | D4: Pollution maps | E4: Missed pollution | F4: F6 (infra) | G4: Pollution levels | H4: Panic
A5: Land & Water Stewardship | B5: Manage land/water | C5: Maps | D5: Stewardship plans | E5: Mismanagement | F5: F10 (standards) | G5: Stewardship score | H5: Displacement
A6: Regeneration Systems | B6: Restore ecosystems | C6: Data | D6: Regeneration plans | E6: Failure | F6: F5 (behaviour) | G6: Regeneration rate | H6: Over‑restoration
A7: Ecological Risk Assessment | B7: Assess ecological risks | C7: Data | D7: Risk reports | E7: Mis‑ranking | F7: F2 (risk) | G7: Risk accuracy | H7: Over‑caution
A8: Planetary Boundary Compliance | B8: Track boundary use | C8: Indicators | D8: Compliance reports | E8: Boundary breach | F8: F8 (integration) | G8: Boundary index | H8: Restrictive policies
A9: Environmental Externality Mapping | B9: Map externalities | C9: Data | D9: Externality maps | E9: Blind spots | F9: F3 (data) | G9: Externality accuracy | H9: Over‑correction

Sheet F8
A1: Subsystem | B1: Purpose | C1: Inputs | D1: Outputs | E1: Risks | F1: Interfaces | G1: Metrics | H1: Externalities
A2: Dependency Mapping | B2: Map dependencies | C2: Workflows | D2: Dependency graphs | E2: Missing links | F2: All Families | G2: Graph completeness | H2: Over‑mapping
A3: Cross‑Family Workflow Integration | B3: Integrate workflows | C3: Processes | D3: Integrated flows | E3: Breaks | F3: F1–F10 | G3: Integration score | H3: Over‑coupling
A4: Externality Propagation | B4: Track externalities | C4: Signals | D4: Propagation maps | E4: Missed propagation | F4: F7 (ecology) | G4: Propagation accuracy | H4: Panic
A5: Systemic Health Monitoring | B5: Monitor system health | C5: Metrics | D5: Health index | E5: Blind spots | F5: F4 (feedback) | G5: Health accuracy | H5: Over‑reaction
A6: Interoperability Management | B6: Ensure interoperability | C6: Standards | D6: Interop reports | E6: Incompatibility | F6: F10 (standards) | G6: Interop score | H6: Over‑standardisation
A7: Integration Failure Detection | B7: Detect integration failures | C7: Logs | D7: Alerts | E7: Missed failures | F7: F3 (audit) | G7: Detection rate | H7: False alarms
A8: Cross‑System Coordination | B8: Coordinate systems | C8: Signals | D8: Coordination events | E8: Mis‑coordination | F8: F2 (risk) | G8: Coordination score | H8: Over‑coordination
A9: System‑of‑Systems Governance | B9: Govern the whole system | C9: All inputs | D9: Governance signals | E9: Overreach | F9: F1 (governance) | G9: Governance clarity | H9: Centralisation

Sheet F9
A1: Subsystem | B1: Purpose | C1: Inputs | D1: Outputs | E1: Risks | F1: Interfaces | G1: Metrics | H1: Externalities
A2: Identity & Authentication | B2: Identify actors | C2: Credentials | D2: Auth events | E2: Identity theft | F2: F3 (audit) | G2: Auth accuracy | H2: Exclusion
A3: Messaging Protocols | B3: Enable communication | C3: Messages | D3: Delivered messages | E3: Loss | F3: F2 (risk) | G3: Delivery rate | H3: Noise
A4: Core Records & Registries | B4: Maintain records | C4: Data | D4: Records | E4: Corruption | F4: F10 (standards) | G4: Record integrity | H4: Privacy
A5: Authorisation & Access Control | B5: Control access | C5: Roles | D5: Access events | E5: Privilege creep | F5: F1 (roles) | G5: Access violations | H5: Over‑restriction
A6: Foundational Data Schemas | B6: Define schemas | C6: Standards | D6: Schemas | E6: Schema drift | F6: F3 (data) | G6: Schema compliance | H6: Rigidity
A7: Time & Addressing | B7: Provide time/address | C7: Clocks | D7: Timestamps | E7: Drift | F7: F6 (infra) | G7: Time accuracy | H7: Over‑precision
A8: Core Interoperability Protocols | B8: Enable interop | C8: Standards | D8: Protocols | E8: Breakage | F8: F8 (integration) | G8: Protocol uptime | H8: Over‑coupling
A9: Foundational Compliance | B9: Ensure safety | C9: Rules | D9: Compliance signals | E9: Non‑compliance | F9: F5 (behaviour) | G9: Compliance rate | H9: Over‑compliance

Sheet F10
A1: Subsystem | B1: Purpose | C1: Inputs | D1: Outputs | E1: Risks | F1: Interfaces | G1: Metrics | H1: Externalities
A2: Standards Development | B2: Create standards | C2: Proposals | D2: Drafts | E2: Capture | F2: F4 (feedback) | G2: Draft quality | H2: Over‑standardisation
A3: Versioning & Change Control | B3: Manage versions | C3: Changes | D3: Versions | E3: Drift | F3: F3 (audit) | G3: Version clarity | H3: Update fatigue
A4: Cross‑Standard Harmonisation | B4: Align standards | C4: Standards | D4: Harmonised sets | E4: Conflict | F4: F8 (integration) | G4: Harmony score | H4: Over‑alignment
A5: Compliance & Certification | B5: Certify compliance | C5: Tests | D5: Certificates | E5: False certs | F5: F7 (ecology) | G5: Cert accuracy | H5: Compliance burden
A6: Reference Implementations | B6: Provide examples | C6: Standards | D6: RIs | E6: Over‑complexity | F6: F9 (protocols) | G6: RI minimalism | H6: De‑facto capture
A7: Registries & Canonical Records | B7: Store standards | C7: Data | D7: Registries | E7: Corruption | F7: F3 (audit) | G7: Registry integrity | H7: Rigidity
A8: Public Reasoning & Transparency | B8: Publish reasoning | C8: Logs | D8: Reasoning | E8: Opaqueness | F8: F4 (feedback) | G8: Transparency score | H8: Over‑exposure
A9: Anti‑Capture Safeguards | B9: Prevent capture | C9: Signals | D9: Safeguards | E9: Capture | F9: F1 (oversight) | G9: Capture risk | H9: Over‑constraints

Sheet Index
A1: Family | B1: Sheet Name | C1: Description

Sheet Cross Family Summary
A1: Family | B1: Subsystem | C1: Purpose | D1: Inputs | E1: Outputs | F1: Risks | G1: Interfaces | H1: Metrics | I1: Externalities
A2: F1 – Governance & Oversight | B2: Decision Systems & Mandates | C2: ='F1'!B2 -> Define how decisions are made, by whom, under what authority | D2: ='F1'!C2 -> Mandates, roles, constraints, data, proposals | E2: ='F1'!D2 -> Decisions, approvals, rejections, rationale | F2: ='F1'!E2 -> Unclear authority, decision bottlenecks, capture | G2: ='F1'!F2 -> F3 (data), F4 (feedback), F5 (incentives) | H2: ='F1'!G2 -> Decision latency, decision accuracy, mandate clarity | I2: ='F1'!H2 -> Power concentration, opaque decisions
A3: F1 – Governance & Oversight | B3: Institutional Architecture & Roles | C3: ='F1'!B3 -> Define structure, roles, responsibilities | D3: ='F1'!C3 -> Org charts, mandates, legal constraints | E3: ='F1'!D3 -> Role definitions, responsibility maps | F3: ='F1'!E3 -> Role ambiguity, duplication, gaps | G3: ='F1'!F3 -> F8 (integration), F10 (standards) | H3: ='F1'!G3 -> Role clarity, overlap index | I3: ='F1'!H3 -> Institutional rigidity
A4: F1 – Governance & Oversight | B4: Transparency & Public Records | C4: ='F1'!B4 -> Ensure decisions and actions are visible | D4: ='F1'!C4 -> Logs, decisions, data, records | E4: ='F1'!D4 -> Public records, disclosures | F4: ='F1'!E4 -> Hidden actions, incomplete records | G4: ='F1'!F4 -> F3 (audit), F4 (feedback) | H4: ='F1'!G4 -> Transparency coverage, record completeness | I4: ='F1'!H4 -> Privacy leakage
A5: F1 – Governance & Oversight | B5: Accountability & Oversight | C5: ='F1'!B5 -> Detect and correct misuse, errors, misconduct | D5: ='F1'!C5 -> Reports, audits, complaints | E5: ='F1'!D5 -> Corrective actions, sanctions | F5: ='F1'!E5 -> Oversight capture, weak enforcement | G5: ='F1'!F5 -> F3 (audit), F5 (incentives) | H5: ='F1'!G5 -> Oversight response time, enforcement rate | I5: ='F1'!H5 -> Chilling effects
A6: F1 – Governance & Oversight | B6: Ethics, Integrity & Anti‑Corruption | C6: ='F1'!B6 -> Prevent corruption, conflicts, unethical behaviour | D6: ='F1'!C6 -> Declarations, audits, incentives | E6: ='F1'!D6 -> Integrity reports, conflict flags | F6: ='F1'!E6 -> Corruption, conflicts of interest | G6: ='F1'!F6 -> F5 (incentives), F3 (audit) | H6: ='F1'!G6 -> Conflict detection rate, integrity score | I6: ='F1'!H6 -> Over‑compliance burden
A7: F1 – Governance & Oversight | B7: Dispute Resolution & Redress | C7: ='F1'!B7 -> Resolve disputes fairly and consistently | D7: ='F1'!C7 -> Complaints, evidence, rules | E7: ='F1'!D7 -> Resolutions, remedies | F7: ='F1'!E7 -> Bias, backlog, inconsistent rulings | G7: ='F1'!F7 -> F4 (feedback), F1 (mandates) | H7: ='F1'!G7 -> Resolution time, fairness index | I7: ='F1'!H7 -> Strategic complaints
A8: F1 – Governance & Oversight | B8: Delegation & Escalation Paths | C8: ='F1'!B8 -> Ensure decisions escalate or delegate correctly | D8: ='F1'!C8 -> Mandates, thresholds, workflows | E8: ='F1'!D8 -> Escalation events, delegated actions | F8: ='F1'!E8 -> Escalation failure, overload | G8: ='F1'!F8 -> F2 (risk), F8 (integration) | H8: ='F1'!G8 -> Escalation correctness, overload frequency | I8: ='F1'!H8 -> Over‑centralisation
A9: F1 – Governance & Oversight | B9: Legitimacy & Consent Maintenance | C9: ='F1'!B9 -> Maintain public trust and consent | D9: ='F1'!C9 -> Sentiment, participation, transparency | E9: ='F1'!D9 -> Legitimacy signals, trust reports | F9: ='F1'!E9 -> Loss of legitimacy, disengagement | G9: ='F1'!F9 -> F4 (feedback), F5 (behaviour) | H9: ='F1'!G9 -> Trust index, participation rate | I9: ='F1'!H9 -> Populist capture
A10: F2 – Risk & Coordination | B10: Hazard Detection & Early Warning | C10: ='F2'!B2 -> Detect emerging risks early | D10: ='F2'!C2 -> Sensors, reports, data streams | E10: ='F2'!D2 -> Alerts, warnings | F10: ='F2'!E2 -> Missed signals, false positives | G10: ='F2'!F2 -> F3 (data), F7 (ecology) | H10: ='F2'!G2 -> Detection latency, false‑positive rate | I10: ='F2'!H2 -> Alarm fatigue
A11: F2 – Risk & Coordination | B11: Risk Assessment & Prioritisation | C11: ='F2'!B3 -> Rank risks by severity and likelihood | D11: ='F2'!C3 -> Hazard data, models | E11: ='F2'!D3 -> Risk scores, priority lists | F11: ='F2'!E3 -> Mis‑prioritisation, bias | G11: ='F2'!F3 -> F5 (behaviour), F8 (integration) | H11: ='F2'!G3 -> Prioritisation accuracy | I11: ='F2'!H3 -> Resource misallocation
A12: F2 – Risk & Coordination | B12: Crisis Coordination | C12: ='F2'!B4 -> Coordinate multi‑actor response | D12: ='F2'!C4 -> Alerts, resources, mandates | E12: ='F2'!D4 -> Coordinated actions | F12: ='F2'!E4 -> Coordination failure | G12: ='F2'!F4 -> F1 (governance), F6 (infrastructure) | H12: ='F2'!G4 -> Response time, coordination score | I12: ='F2'!H4 -> Over‑centralisation
A13: F2 – Risk & Coordination | B13: Continuity Planning | C13: ='F2'!B5 -> Ensure operations survive disruptions | D13: ='F2'!C5 -> Dependencies, workflows | E13: ='F2'!D5 -> Continuity plans | F13: ='F2'!E5 -> Plan failure, outdated plans | G13: ='F2'!F5 -> F8 (integration), F6 (infra) | H13: ='F2'!G5 -> Continuity coverage | I13: ='F2'!H5 -> Over‑resilience cost
A14: F2 – Risk & Coordination | B14: Escalation & De‑escalation | C14: ='F2'!B6 -> Manage crisis intensity | D14: ='F2'!C6 -> Thresholds, signals | E14: ='F2'!D6 -> Escalation events | F14: ='F2'!E6 -> Late escalation, premature de‑escalation | G14: ='F2'!F6 -> F1 (delegation), F4 (feedback) | H14: ='F2'!G6 -> Escalation correctness | I14: ='F2'!H6 -> Panic amplification
A15: F2 – Risk & Coordination | B15: Resource Mobilisation | C15: ='F2'!B7 -> Deploy resources efficiently | D15: ='F2'!C7 -> Inventories, logistics | E15: ='F2'!D7 -> Resource deployments | F15: ='F2'!E7 -> Shortages, misallocation | G15: ='F2'!F7 -> F6 (infra), F2 (coordination) | H15: ='F2'!G7 -> Deployment speed | I15: ='F2'!H7 -> Resource depletion
A16: F2 – Risk & Coordination | B16: Post‑Incident Review | C16: ='F2'!B8 -> Learn from failures | D16: ='F2'!C8 -> Logs, outcomes | E16: ='F2'!D8 -> Lessons, recommendations | F16: ='F2'!E8 -> Blame games, ignored lessons | G16: ='F2'!F8 -> F3 (audit), F1 (oversight) | H16: ='F2'!G8 -> Lesson adoption rate | I16: ='F2'!H8 -> Over‑correction
A17: F2 – Risk & Coordination | B17: Cross‑System Synchronisation | C17: ='F2'!B9 -> Align responses across systems | D17: ='F2'!C9 -> Signals, dependencies | E17: ='F2'!D9 -> Synchronised actions | F17: ='F2'!E9 -> Desynchronisation | G17: ='F2'!F9 -> F8 (integration) | H17: ='F2'!G9 -> Sync accuracy | I17: ='F2'!H9 -> Cascading failures
A18: F3 – Data Integrity & Audit | B18: Data Provenance & Lineage | C18: ='F3'!B2 -> Track where data comes from | D18: ='F3'!C2 -> Raw data, metadata | E18: ='F3'!D2 -> Provenance chains | F18: ='F3'!E2 -> Missing lineage | G18: ='F3'!F2 -> F9 (records), F10 (standards) | H18: ='F3'!G2 -> Provenance completeness | I18: ='F3'!H2 -> Privacy exposure
A19: F3 – Data Integrity & Audit | B19: Validation & Verification | C19: ='F3'!B3 -> Ensure data is correct | D19: ='F3'!C3 -> Data, schemas | E19: ='F3'!D3 -> Validated data | F19: ='F3'!E3 -> Invalid data passing | G19: ='F3'!F3 -> F5 (behaviour), F3 (audit) | H19: ='F3'!G3 -> Validation accuracy | I19: ='F3'!H3 -> Over‑strict validation
A20: F3 – Data Integrity & Audit | B20: Audit Trails & Logging | C20: ='F3'!B4 -> Record actions and changes | D20: ='F3'!C4 -> Events, actions | E20: ='F3'!D4 -> Logs | F20: ='F3'!E4 -> Log tampering | G20: ='F3'!F4 -> F1 (oversight) | H20: ='F3'!G4 -> Log completeness | I20: ='F3'!H4 -> Storage overhead
A21: F3 – Data Integrity & Audit | B21: Quality Assurance | C21: ='F3'!B5 -> Maintain data quality | D21: ='F3'!C5 -> Data, rules | E21: ='F3'!D5 -> QA reports | F21: ='F3'!E5 -> Quality drift | G21: ='F3'!F5 -> F8 (integration) | H21: ='F3'!G5 -> Error rate | I21: ='F3'!H5 -> Over‑cleaning
A22: F3 – Data Integrity & Audit | B22: Tamper Detection | C22: ='F3'!B6 -> Detect manipulation | D22: ='F3'!C6 -> Logs, hashes | E22: ='F3'!D6 -> Alerts | F22: ='F3'!E6 -> Undetected tampering | G22: ='F3'!F6 -> F2 (risk) | H22: ='F3'!G6 -> Detection rate | I22: ='F3'!H6 -> False alarms
A23: F3 – Data Integrity & Audit | B23: Access Control Audit | C23: ='F3'!B7 -> Ensure correct access | D23: ='F3'!C7 -> Permissions, logs | E23: ='F3'!D7 -> Access reports | F23: ='F3'!E7 -> Privilege creep | G23: ='F3'!F7 -> F9 (auth) | H23: ='F3'!G7 -> Access violations | I23: ='F3'!H7 -> Over‑restriction
A24: F3 – Data Integrity & Audit | B24: Data Retention & Archival | C24: ='F3'!B8 -> Preserve data correctly | D24: ='F3'!C8 -> Records, policies | E24: ='F3'!D8 -> Archives | F24: ='F3'!E8 -> Loss, corruption | G24: ='F3'!F8 -> F10 (standards) | H24: ='F3'!G8 -> Retention compliance | I24: ='F3'!H8 -> Storage cost
A25: F3 – Data Integrity & Audit | B25: Cross‑System Reconciliation | C25: ='F3'!B9 -> Align data across systems | D25: ='F3'!C9 -> Multiple datasets | E25: ='F3'!D9 -> Reconciled data | F25: ='F3'!E9 -> Inconsistency | G25: ='F3'!F9 -> F8 (integration) | H25: ='F3'!G9 -> Reconciliation accuracy | I25: ='F3'!H9 -> Forced uniformity
A26: F4 – Civic Feedback & Cultural | B26: Sentiment & Narrative Monitoring | C26: ='F4'!B2 -> Track public mood | D26: ='F4'!C2 -> Media, surveys | E26: ='F4'!D2 -> Sentiment signals | F26: ='F4'!E2 -> Misinterpretation | G26: ='F4'!F2 -> F5 (behaviour) | H26: ='F4'!G2 -> Sentiment accuracy | I26: ='F4'!H2 -> Manipulation
A27: F4 – Civic Feedback & Cultural | B27: Public Feedback Channels | C27: ='F4'!B3 -> Capture public input | D27: ='F4'!C3 -> Forms, calls | E27: ='F4'!D3 -> Feedback data | F27: ='F4'!E3 -> Low participation | G27: ='F4'!F3 -> F1 (legitimacy) | H27: ='F4'!G3 -> Participation rate | I27: ='F4'!H3 -> Feedback overload
A28: F4 – Civic Feedback & Cultural | B28: Cultural Signal Tracking | C28: ='F4'!B4 -> Track cultural shifts | D28: ='F4'!C4 -> Trends, events | E28: ='F4'!D4 -> Cultural indicators | F28: ='F4'!E4 -> Bias | G28: ='F4'!F4 -> F7 (ecology) | H28: ='F4'!G4 -> Cultural drift | I28: ='F4'!H4 -> Cultural homogenisation
A29: F4 – Civic Feedback & Cultural | B29: Community Engagement | C29: ='F4'!B5 -> Maintain community ties | D29: ='F4'!C5 -> Meetings, outreach | E29: ='F4'!D5 -> Engagement reports | F29: ='F4'!E5 -> Tokenism | G29: ='F4'!F5 -> F4 (feedback) | H29: ='F4'!G5 -> Engagement depth | I29: ='F4'!H5 -> Over‑consultation
A30: F4 – Civic Feedback & Cultural | B30: Complaint & Redress Intake | C30: ='F4'!B6 -> Capture grievances | D30: ='F4'!C6 -> Complaints | E30: ='F4'!D6 -> Cases | F30: ='F4'!E6 -> Backlogs | G30: ='F4'!F6 -> F1 (redress) | H30: ='F4'!G6 -> Resolution time | I30: ='F4'!H6 -> Strategic complaints
A31: F4 – Civic Feedback & Cultural | B31: Trust & Legitimacy Monitoring | C31: ='F4'!B7 -> Track trust levels | D31: ='F4'!C7 -> Sentiment, behaviour | E31: ='F4'!D7 -> Trust reports | F31: ='F4'!E7 -> Misreading trust | G31: ='F4'!F7 -> F1 (legitimacy) | H31: ='F4'!G7 -> Trust index | I31: ='F4'!H7 -> Trust manipulation
A32: F4 – Civic Feedback & Cultural | B32: Public Information & Communication | C32: ='F4'!B8 -> Communicate clearly | D32: ='F4'!C8 -> Data, decisions | E32: ='F4'!D8 -> Public messages | F32: ='F4'!E8 -> Misinformation | G32: ='F4'!F8 -> F2 (risk) | H32: ='F4'!G8 -> Clarity score | I32: ='F4'!H8 -> Over‑communication
A33: F4 – Civic Feedback & Cultural | B33: Cultural Impact Assessment | C33: ='F4'!B9 -> Assess cultural effects | D33: ='F4'!C9 -> Policies, actions | E33: ='F4'!D9 -> Impact reports | F33: ='F4'!E9 -> Blind spots | G33: ='F4'!F9 -> F5 (behaviour) | H33: ='F4'!G9 -> Impact accuracy | I33: ='F4'!H9 -> Cultural distortion
A34: F5 – Incentives & Behavioural | B34: Behavioural Modelling | C34: ='F5'!B2 -> Predict behaviour | D34: ='F5'!C2 -> Data, signals | E34: ='F5'!D2 -> Models | F34: ='F5'!E2 -> Wrong predictions | G34: ='F5'!F2 -> F3 (data) | H34: ='F5'!G2 -> Model accuracy | I34: ='F5'!H2 -> Behavioural stereotyping
A35: F5 – Incentives & Behavioural | B35: Incentive Design | C35: ='F5'!B3 -> Shape behaviour | D35: ='F5'!C3 -> Goals, models | E35: ='F5'!D3 -> Incentives | F35: ='F5'!E3 -> Perverse incentives | G35: ='F5'!F3 -> F1 (governance) | H35: ='F5'!G3 -> Incentive effectiveness | I35: ='F5'!H3 -> Gaming
A36: F5 – Incentives & Behavioural | B36: Influence Mapping | C36: ='F5'!B4 -> Map influence flows | D36: ='F5'!C4 -> Networks, data | E36: ='F5'!D4 -> Influence maps | F36: ='F5'!E4 -> Misidentification | G36: ='F5'!F4 -> F4 (culture) | H36: ='F5'!G4 -> Influence accuracy | I36: ='F5'!H4 -> Stigmatisation
A37: F5 – Incentives & Behavioural | B37: Motivation & Compliance | C37: ='F5'!B5 -> Maintain compliance | D37: ='F5'!C5 -> Rules, incentives | E37: ='F5'!D5 -> Compliance signals | F37: ='F5'!E5 -> Non‑compliance | G37: ='F5'!F5 -> F10 (standards) | H37: ='F5'!G5 -> Compliance rate | I37: ='F5'!H5 -> Over‑policing
A38: F5 – Incentives & Behavioural | B38: Perverse Incentive Detection | C38: ='F5'!B6 -> Detect harmful incentives | D38: ='F5'!C6 -> Behaviour data | E38: ='F5'!D6 -> Alerts | F38: ='F5'!E6 -> Missed incentives | G38: ='F5'!F6 -> F2 (risk) | H38: ='F5'!G6 -> Detection rate | I38: ='F5'!H6 -> False positives
A39: F5 – Incentives & Behavioural | B39: Behavioural Impact Assessment | C39: ='F5'!B7 -> Evaluate interventions | D39: ='F5'!C7 -> Data, models | E39: ='F5'!D7 -> Impact reports | F39: ='F5'!E7 -> Misattribution | G39: ='F5'!F7 -> F8 (integration) | H39: ='F5'!G7 -> Impact accuracy | I39: ='F5'!H7 -> Over‑attribution
A40: F5 – Incentives & Behavioural | B40: Feedback Loop Design | C40: ='F5'!B8 -> Create adaptive loops | D40: ='F5'!C8 -> Signals, incentives | E40: ='F5'!D8 -> Loops | F40: ='F5'!E8 -> Instability | G40: ='F5'!F8 -> F4 (feedback) | H40: ='F5'!G8 -> Loop stability | I40: ='F5'!H8 -> Over‑tight coupling
...
